Workbook
Name UPDATE: 'Data Sheet'!$E$1

Sheet One Page Profile
B2: ='Data Sheet'!B1&" - "&" One Page Profile" -> HINDUSTAN UNILEVER LTD - One Page Profile
C4: ='Input Sheet'!C4 -> Hindustan Unilever Limited (HUL) is an Indian fast-moving consumer goods company, headquartered in Mumbai. It is a subsidiary of the Anglo-Dutch company Unilever. Its products include foods, beverages, cleaning agents, personal care products and other consumer staples.
B5: INR(Crs)
B6: Key Financial Metrics | C6: ='Data Sheet'!G16 -> 44286 | D6: ='Data Sheet'!H16 -> 44651 | E6: ='Data Sheet'!I16 -> 45016 | F6: ='Data Sheet'!J16 -> 45382 | G6: ='Data Sheet'!K16 -> 45747 | I6: Share Price-5year
B8: Total Sales | C8: ='Data Sheet'!G17 -> 47028 | D8: ='Data Sheet'!H17 -> 52446 | E8: ='Data Sheet'!I17 -> 60580 | F8: ='Data Sheet'!J17 -> 61896 | G8: ='Data Sheet'!K17 -> 63121
B9: Sales Growth (y-o-y) | C9: ='Profit & Loss'!G27 -> 0.18211296 | D9: ='Profit & Loss'!H27 -> 0.11520796 | E9: ='Profit & Loss'!I27 -> 0.15509286 | F9: ='Profit & Loss'!J27 -> 0.021723341 | G9: ='Profit & Loss'!K27 -> 0.019791263
B10: Gross Profit Margins(%) | C10: ='Profit & Loss'!G30 -> 0.49491792 | D10: ='Profit & Loss'!H30 -> 0.49347901 | E10: ='Profit & Loss'!I30 -> 0.46059756 | F10: ='Profit & Loss'!J30 -> 0.50458834 | G10: ='Profit & Loss'!K30 -> 0.49687109
B11: EBIDTA Margins(%) | C11: ='Profit & Loss'!G31 -> 0.24721443 | D11: ='Profit & Loss'!H31 -> 0.24514739 | E11: ='Profit & Loss'!I31 -> 0.23352592 | F11: ='Profit & Loss'!J31 -> 0.23683275 | G11: ='Profit & Loss'!K31 -> 0.23515153
B12: EBIT Margins (%) | C12: ='Profit & Loss'!G33 -> 0.22437697 | D12: ='Profit & Loss'!H33 -> 0.22434504 | E12: ='Profit & Loss'!I33 -> 0.21475735 | F12: ='Profit & Loss'!J33 -> 0.21718689 | G12: ='Profit & Loss'!K33 -> 0.21368483
B13: Net Profit Margins (%) | C13: ='Profit & Loss'!G32 -> 0.1700051 | D13: ='Profit & Loss'!H32 -> 0.16929794 | E13: ='Profit & Loss'!I32 -> 0.16705183 | F13: ='Profit & Loss'!J32 -> 0.16603658 | G13: ='Profit & Loss'!K32 -> 0.16870772
B14: Earning Per Share (in Rs) | C14: ='Profit & Loss'!G13 -> 34.027068 | D14: ='Profit & Loss'!H13 -> 37.789411 | E14: ='Profit & Loss'!I13 -> 43.071161 | F14: ='Profit & Loss'!J13 -> 43.73936 | G14: ='Profit & Loss'!K13 -> 45.322608
B15: EPS Growth (y-o-y) | C15: ='Profit & Loss'!G34 -> 0.091609332 | D15: ='Profit & Loss'!H34 -> 0.11056911 | E15: ='Profit & Loss'!I34 -> 0.13976799 | F15: ='Profit & Loss'!J34 -> 0.015513834 | G15: ='Profit & Loss'!K34 -> 0.036197334
B16: Divident Per Share (in Rs) | C16: ='Profit & Loss'!G35 -> 40.506895 | D16: ='Profit & Loss'!H35 -> 34.005788 | E16: ='Profit & Loss'!I35 -> 39.006639 | F16: ='Profit & Loss'!J35 -> 42.00715 | G16: ='Profit & Loss'!K35 -> 53.009023
B17: DPS Growth (y-o-y) | C17: ='Profit & Loss'!G36 -> 0.6238764 | D17: ='Profit & Loss'!H36 -> -0.16049383 | E17: ='Profit & Loss'!I36 -> 0.14705882 | F17: ='Profit & Loss'!J36 -> 0.076923077 | G17: ='Profit & Loss'!K36 -> 0.26190476
B19: Key Financial Ratios | C19: =C6 -> 44286 | D19: =C19+365 -> 44651 | E19: =D19+365 -> 45016 | F19: =E19+365 -> 45381 | G19: =F19+365 -> 45746 | I19: Volumes - 5year
B21: Price to Earning | C21: ='Profit & Loss'!G14 -> 68.390258 | D21: ='Profit & Loss'!H14 -> 51.884905 | E21: ='Profit & Loss'!I14 -> 56.892824 | F21: ='Profit & Loss'!J14 -> 49.546678 | G21: ='Profit & Loss'!K14 -> 47.699815
B22: EV/EBIDTA | C22: ='Profit & Loss'!G43 -> 46.646234 | D22: ='Profit & Loss'!H43 -> 35.613524 | E22: ='Profit & Loss'!I43 -> 40.453551 | F22: ='Profit & Loss'!J43 -> 34.321319 | G22: ='Profit & Loss'!K43 -> 33.823979
B23: EV/Sales | C23: ='Profit & Loss'!G44 -> 11.531622 | D23: ='Profit & Loss'!H44 -> 8.7305623 | E23: ='Profit & Loss'!I44 -> 9.4469525 | F23: ='Profit & Loss'!J44 -> 8.1284124 | G23: ='Profit & Loss'!K44 -> 7.9537606
B24: Price to Book Value | C24: ='Profit & Loss'!G46 -> 11.469147 | D24: ='Profit & Loss'!H46 -> 9.3900669 | E24: ='Profit & Loss'!I46 -> 11.445519 | F24: ='Profit & Loss'!J46 -> 9.9416458 | G24: ='Profit & Loss'!K46 -> 10.28208
B25: Return on Equity(%) | C25: ='Balance Sheet'!G23 -> 0.16770147 | D25: ='Balance Sheet'!H23 -> 0.18097878 | E25: ='Balance Sheet'!I23 -> 0.20117684 | F25: ='Balance Sheet'!J23 -> 0.20065211 | G25: ='Balance Sheet'!K23 -> 0.21555807
B26: Return on Capital Employed(%) | C26: ='Balance Sheet'!G24 -> 0.38359301 | D26: ='Balance Sheet'!H24 -> 0.24514717 | E26: ='Balance Sheet'!I24 -> 0.26485088 | F26: ='Balance Sheet'!J24 -> 0.27363876 | G26: ='Balance Sheet'!K24 -> 0.28548847
B28: Top 10 Share Holders | C28: No. Share Held (in cr.) | E28: %Holding | F28: Market Value(in cr.) | I28: Share Holding-Pattern
B29: ='Raw Data'!G1159 -> UNILEVER PLC | C29: ='Raw Data'!H1159 -> 111.43701 | E29: ='Raw Data'!I1159 -> 0.4743 | F29: ='Raw Data'!J1159 -> 252142.96
B30: ='Raw Data'!G1160 -> LIFE INSURANCE CORPORATION OF INDIA | C30: ='Raw Data'!H1160 -> 15.743276 | E30: ='Raw Data'!I1160 -> 0.067 | F30: ='Raw Data'!J1160 -> 35621.524
B31: ='Raw Data'!G1161 -> UNILEVER GROUP LIMITED | C31: ='Raw Data'!H1161 -> 10.673946 | E31: ='Raw Data'!I1161 -> 0.0454 | F31: ='Raw Data'!J1161 -> 24151.404
B32: ='Raw Data'!G1162 -> UNILEVER OVERSEAS HOLDINGS AG | C32: ='Raw Data'!H1162 -> 6.878432 | E32: ='Raw Data'!I1162 -> 0.0293 | F32: ='Raw Data'!J1162 -> 15563.484
B33: ='Raw Data'!G1163 -> UNILEVER UK&CN HOLDINGS LIMITED | C33: ='Raw Data'!H1163 -> 6.008625 | E33: ='Raw Data'!I1163 -> 0.0256 | F33: ='Raw Data'!J1163 -> 13595.415
B34: ='Raw Data'!G1164 -> UNILEVER SOUTH INDIA ESTATES LIMITED | C34: ='Raw Data'!H1164 -> 5.27472 | E34: ='Raw Data'!I1164 -> 0.0224 | F34: ='Raw Data'!J1164 -> 11934.845
B35: ='Raw Data'!G1165 -> SBI ESG EXCLUSIONARY STRATEGY FUND | C35: ='Raw Data'!H1165 -> 3.8897573 | E35: ='Raw Data'!I1165 -> 0.0166 | F35: ='Raw Data'!J1165 -> 8801.1594
B36: ='Raw Data'!G1166 -> ICICI PRUDENTIAL SENSEX ETF | C36: ='Raw Data'!H1166 -> 3.4496318 | E36: ='Raw Data'!I1166 -> 0.0147 | F36: ='Raw Data'!J1166 -> 7805.3094
B37: ='Raw Data'!G1167 -> UNILEVER ASSAM ESTATES LIMITED | C37: ='Raw Data'!H1167 -> 3.282048 | E37: ='Raw Data'!I1167 -> 0.014 | F37: ='Raw Data'!J1167 -> 7426.1259
B38: ='Raw Data'!G1168 -> UNILEVER OVERSEAS HOLDINGS B V | C38: ='Raw Data'!H1168 -> 1.8865 | E38: ='Raw Data'!I1168 -> 0.008 | F38: ='Raw Data'!J1168 -> 4268.4892
B40: Managerial remuneration (FY 25) | C40: Designation | D40: Remuneration | F40: X of Median Salary | I40: Capital Structure
B42: Nitin Paranjpe@ | C42: Chairman | D42: - | F42: NA | I42: Share Price as on 4 Mar 2026 | K42: ='Data Sheet'!B8 -> 2261.3
B43: Rohit Jawa | C43: Ceo & MD | D43: 23.23 | F43: 146.47 | I43: Number of Shares o/s | K43: ='Data Sheet'!B6 -> 235.04015
B44: Ritesh Tiwari | C44: Ex. Director & CFO | D44: 9.39 | F44: 59.18 | I44: Market Capitalisation | K44: =K42*K43 -> 531496.3
B45: BP Biddappa | C45: Ex. Director | D45: 8.87 | F45: 66.32 | I45: Less: Cash & Equivalents | K45: =-'Data Sheet'!K69 -> -7554
B46: Dev Bajpai | C46: Ex. Director and CS | D46: 9.95 | F46: 83.65 | I46: Add : Total Debt | K46: ='Data Sheet'!K59 -> 1648
I47: Enterprise Value | K47: =SUM(K44:K46) -> 525590.3
B48: Note: @ The Non-Executive Chairman of the Company did not receive any sitting fees, commission or stock options from the Company
...

Sheet Data>

Sheet Data Sheet
A1: COMPANY NAME | B1: HINDUSTAN UNILEVER LTD | E1: =IF(B2<>B3, "A NEW VERSION OF THE WORKSHEET IS AVAILABLE", "")
A2: LATEST VERSION | B2: 2.1 | E2: PLEASE DO NOT MAKE ANY CHANGES TO THIS SHEET
A3: CURRENT VERSION | B3: 2.1
A5: META
A6: Number of shares | B6: =IF(B9>0, B9/B8, 0) -> 235.04015
A7: Face Value | B7: 1
A8: Current Price | B8: 2261.3
A9: Market Capitalization | B9: 531496.3
A15: PROFIT & LOSS
A16: Report Date | B16: 42460 | C16: 42825 | D16: 43190 | E16: 43555 | F16: 43921 | G16: 44286 | H16: 44651 | I16: 45016 | J16: 45382 | K16: 45747
A17: Sales | B17: 32186 | C17: 33162 | D17: 35545 | E17: 39310 | F17: 39783 | G17: 47028 | H17: 52446 | I17: 60580 | J17: 61896 | K17: 63121
A18: Raw Material Cost | B18: 13184 | C18: 13606 | D18: 14233 | E18: 15845 | F18: 15697 | G18: 20141 | H18: 22871 | I18: 28427 | J18: 26822 | K18: 27344
A19: Change in Inventory | B19: -83 | C19: -144 | D19: 72 | E19: -12 | F19: 108 | G19: 405 | H19: 22 | I19: 75 | J19: 11 | K19: 153
A20: Power and Fuel | B20: 309 | C20: 295 | D20: 295 | E20: 308 | F20: 299 | G20: 339 | H20: 318 | I20: 384 | J20: 446 | K20: 427
A21: Other Mfr. Exp | B21: 2966 | C21: 2887 | D21: 2998 | E21: 3041 | F21: 2906 | G21: 2868 | H21: 3354 | I21: 3791 | J21: 3385 | K21: 3834
A22: Employee Cost | B22: 1680 | C22: 1743 | D22: 1860 | E22: 1875 | F22: 1820 | G22: 2358 | H22: 2545 | I22: 2854 | J22: 3009 | K22: 3077
A23: Selling and admin | B23: 6741 | C23: 6689 | D23: 7252 | E23: 7796 | F23: 7620 | G23: 7906 | H23: 8164 | I23: 8785 | J23: 10780 | K23: 10693
A24: Other Expenses | B24: 1313 | C24: 1470 | D24: 1480 | E24: 1553 | F24: 1688 | G24: 2195 | H24: 2359 | I24: 2267 | J24: 2806 | K24: 3056
A25: Other Income | B25: 486 | C25: 606 | D25: 353 | E25: 322 | F25: 424 | G25: 170 | H25: 219 | I25: 448 | J25: 817 | K25: 1322
A26: Depreciation | B26: 353 | C26: 432 | D26: 520 | E26: 565 | F26: 1002 | G26: 1074 | H26: 1091 | I26: 1137 | J26: 1216 | K26: 1355
A27: Interest | B27: 17 | C27: 35 | D27: 26 | E27: 33 | F27: 118 | G27: 117 | H27: 106 | I27: 114 | J27: 334 | K27: 395
... A31: Dividend Amount | B31: 3456 | C31: 3672 | D31: 4320 | E31: 4752 | F31: 5400 | G31: 9517.5 | H31: 7990 | I31: 9165 | J31: 9870 | K31: 12455
A40: Quarters
A41: Report Date | B41: 45199 | C41: 45291 | D41: 45382 | E41: 45473 | F41: 45565 | G41: 45657 | H41: 45747 | I41: 45838 | J41: 45930 | K41: 46022
A42: Sales | B42: 15623 | C42: 15567 | D42: 15210 | E42: 15707 | F42: 15926 | G42: 15556 | H42: 15670 | I42: 16514 | J42: 15919 | K42: 16441
A43: Expenses | B43: 11828 | C43: 11902 | D43: 11675 | E43: 11965 | F43: 12139 | G43: 11867 | H43: 12052 | I43: 12797 | J43: 12137 | K43: 12660
A44: Other Income | B44: 178 | C44: 184 | D44: 309 | E44: 209 | F44: 203 | G44: 733 | H44: 171 | I44: 74 | J44: 269 | K44: 4048
A45: Depreciation | B45: 297 | C45: 313 | D45: 320 | E45: 329 | F45: 338 | G45: 318 | H45: 347 | I45: 361 | J45: 322 | K45: 337
A46: Interest | B46: 88 | C46: 91 | D46: 105 | E46: 93 | F46: 110 | G46: 109 | H46: 80 | I46: 127 | J46: 124 | K46: 88
A47: Profit before tax | B47: 3588 | C47: 3445 | D47: 3419 | E47: 3529 | F47: 3542 | G47: 3995 | H47: 3362 | I47: 3303 | J47: 3605 | K47: 7404
A48: Tax | B48: 931 | C48: 937 | D48: 858 | E48: 917 | F48: 947 | G48: 1006 | H48: 887 | I48: 535 | J48: 911 | K48: 801
A49: Net profit | B49: 2656 | C49: 2509 | D49: 2558 | E49: 2610 | F49: 2591 | G49: 2984 | H49: 2464 | I49: 2756 | J49: 2685 | K49: 6607
A50: Operating Profit | B50: 3795 | C50: 3665 | D50: 3535 | E50: 3742 | F50: 3787 | G50: 3689 | H50: 3618 | I50: 3717 | J50: 3782 | K50: 3781
A55: BALANCE SHEET
A56: Report Date | B56: 42460 | C56: 42825 | D56: 43190 | E56: 43555 | F56: 43921 | G56: 44286 | H56: 44651 | I56: 45016 | J56: 45382 | K56: 45747
A57: Equity Share Capital | B57: 216 | C57: 216 | D57: 216 | E57: 216 | F57: 216 | G57: 235 | H57: 235 | I57: 235 | J57: 235 | K57: 235
A58: Reserves | B58: 6357 | C58: 6528 | D58: 7065 | E58: 7651 | F58: 8013 | G58: 47439 | H58: 48826 | I58: 50069 | J58: 50983 | K58: 49167
A59: Borrowings | B59: 177 | C59: 277 | E59: 99 | H59: 1043 | I59: 1219 | J59: 1484 | K59: 1648
A60: Other Liabilities | B60: 8043 | C60: 8685 | D60: 10581 | E60: 10663 | F60: 11924 | G60: 21066 | H60: 20402 | I60: 21554 | J60: 25787 | K60: 28813
A61: Total | B61: 14793 | C61: 15706 | D61: 17862 | E61: 18629 | F61: 20153 | G61: 68740 | H61: 70506 | I61: 73077 | J61: 78489 | K61: 79863
...

Sheet Profit & Loss
A1: ='Data Sheet'!B1 -> HINDUSTAN UNILEVER LTD | H1: =UPDATE | M1: SCREENER.IN
A3: Narration | B3: ='Data Sheet'!B16 -> 42460 | C3: ='Data Sheet'!C16 -> 42825 | D3: ='Data Sheet'!D16 -> 43190 | E3: ='Data Sheet'!E16 -> 43555 | F3: ='Data Sheet'!F16 -> 43921 | G3: ='Data Sheet'!G16 -> 44286 | H3: ='Data Sheet'!H16 -> 44651 | I3: ='Data Sheet'!I16 -> 45016 | ... K3: ='Data Sheet'!K16 -> 45747 | L3: Trailing | M3: Best Case | N3: Worst Case
A4: Sales | B4: ='Data Sheet'!B17 -> 32186 | C4: ='Data Sheet'!C17 -> 33162 | D4: ='Data Sheet'!D17 -> 35545 | E4: ='Data Sheet'!E17 -> 39310 | F4: ='Data Sheet'!F17 -> 39783 | G4: ='Data Sheet'!G17 -> 47028 | H4: ='Data Sheet'!H17 -> 52446 | I4: ='Data Sheet'!I17 -> 60580 | ... K4: ='Data Sheet'!K17 -> 63121 | L4: =SUM(Quarters!H4:K4) -> 64544 | M4: =$K4+M23*K4 -> 67142.015 | N4: =$K4+N23*L4 -> 64576.08
A5: Expenses | B5: =SUM('Data Sheet'!B18,'Data Sheet'!B20:B24, -1*'Data Sheet'!B19) -> 26276 | C5: =SUM('Data Sheet'!C18,'Data Sheet'!C20:C24, -1*'Data Sheet'!C19) -> 26834 | D5: =SUM('Data Sheet'!D18,'Data Sheet'!D20:D24, -1*'Data Sheet'!D19) -> 28046 | E5: =SUM('Data Sheet'!E18,'Data Sheet'!E20:E24, -1*'Data Sheet'!E19) -> 30430 | F5: =SUM('Data Sheet'!F18,'Data Sheet'!F20:F24, -1*'Data Sheet'!F19) -> 29922 | G5: =SUM('Data Sheet'!G18,'Data Sheet'!G20:G24, -1*'Data Sheet'!G19) -> 35402 | H5: =SUM('Data Sheet'!H18,'Data Sheet'!H20:H24, -1*'Data Sheet'!H19) -> 39589 | I5: =SUM('Data Sheet'!I18,'Data Sheet'!I20:I24, -1*'Data Sheet'!I19) -> 46433 | ... K5: =SUM('Data Sheet'!K18,'Data Sheet'!K20:K24, -1*'Data Sheet'!K19) -> 48278 | L5: =SUM(Quarters!H5:K5) -> 49646 | M5: =M4-M6 -> 51351.448 | N5: =N4-N6 -> 49772.613
A6: Operating Profit | B6: =B4-B5 -> 5910 | C6: =C4-C5 -> 6328 | D6: =D4-D5 -> 7499 | E6: =E4-E5 -> 8880 | F6: =F4-F5 -> 9861 | G6: =G4-G5 -> 11626 | H6: =H4-H5 -> 12857 | I6: =I4-I5 -> 14147 | ... K6: =K4-K5 -> 14843 | L6: =SUM(Quarters!H6:K6) -> 14898 | M6: =M4*M24 -> 15790.567 | N6: =N4*N24 -> 14803.467
A7: Other Income | B7: ='Data Sheet'!B25 -> 486 | C7: ='Data Sheet'!C25 -> 606 | D7: ='Data Sheet'!D25 -> 353 | E7: ='Data Sheet'!E25 -> 322 | F7: ='Data Sheet'!F25 -> 424 | G7: ='Data Sheet'!G25 -> 170 | H7: ='Data Sheet'!H25 -> 219 | I7: ='Data Sheet'!I25 -> 448 | ... K7: ='Data Sheet'!K25 -> 1322 | L7: =SUM(Quarters!H7:K7) -> 4562 | M7: 0 | N7: 0
A8: Depreciation | B8: ='Data Sheet'!B26 -> 353 | C8: ='Data Sheet'!C26 -> 432 | D8: ='Data Sheet'!D26 -> 520 | E8: ='Data Sheet'!E26 -> 565 | F8: ='Data Sheet'!F26 -> 1002 | G8: ='Data Sheet'!G26 -> 1074 | H8: ='Data Sheet'!H26 -> 1091 | I8: ='Data Sheet'!I26 -> 1137 | ... K8: ='Data Sheet'!K26 -> 1355 | L8: =SUM(Quarters!H8:K8) -> 1367 | M8: =+$L8 -> 1367 | N8: =+$L8 -> 1367
A9: Interest | B9: ='Data Sheet'!B27 -> 17 | C9: ='Data Sheet'!C27 -> 35 | D9: ='Data Sheet'!D27 -> 26 | E9: ='Data Sheet'!E27 -> 33 | F9: ='Data Sheet'!F27 -> 118 | G9: ='Data Sheet'!G27 -> 117 | H9: ='Data Sheet'!H27 -> 106 | I9: ='Data Sheet'!I27 -> 114 | ... K9: ='Data Sheet'!K27 -> 395 | L9: =SUM(Quarters!H9:K9) -> 419 | M9: =+$L9 -> 419 | N9: =+$L9 -> 419
A10: Profit before tax | B10: ='Data Sheet'!B28 -> 6026 | C10: ='Data Sheet'!C28 -> 6467 | D10: ='Data Sheet'!D28 -> 7306 | E10: ='Data Sheet'!E28 -> 8604 | F10: ='Data Sheet'!F28 -> 9165 | G10: ='Data Sheet'!G28 -> 10605 | H10: ='Data Sheet'!H28 -> 11879 | I10: ='Data Sheet'!I28 -> 13344 | ... K10: ='Data Sheet'!K28 -> 14415 | L10: =SUM(Quarters!H10:K10) -> 17674 | M10: =M6+M7-SUM(M8:M9) -> 14004.567 | N10: =N6+N7-SUM(N8:N9) -> 13017.467
A11: Tax | B11: ='Data Sheet'!B29 -> 1875 | C11: ='Data Sheet'!C29 -> 1977 | D11: ='Data Sheet'!D29 -> 2079 | E11: ='Data Sheet'!E29 -> 2544 | F11: ='Data Sheet'!F29 -> 2409 | G11: ='Data Sheet'!G29 -> 2606 | H11: ='Data Sheet'!H29 -> 2987 | I11: ='Data Sheet'!I29 -> 3201 | ... K11: ='Data Sheet'!K29 -> 3744 | L11: =SUM(Quarters!H11:K11) -> 3134 | M11: =IF($L10>0,$L11/$L10,0) -> 0.17732262 | N11: =IF($L10>0,$L11/$L10,0) -> 0.17732262
A12: Net profit | B12: ='Data Sheet'!B30 -> 4151 | C12: ='Data Sheet'!C30 -> 4476 | D12: ='Data Sheet'!D30 -> 5214 | E12: ='Data Sheet'!E30 -> 6054 | F12: ='Data Sheet'!F30 -> 6748 | G12: ='Data Sheet'!G30 -> 7995 | H12: ='Data Sheet'!H30 -> 8879 | I12: ='Data Sheet'!I30 -> 10120 | ... K12: ='Data Sheet'!K30 -> 10649 | L12: =SUM(Quarters!H12:K12) -> 14512 | M12: =M10-M11*M10 -> 11521.24 | N12: =N10-N11*N10 -> 10709.176
A13: EPS | B13: =IF('Data Sheet'!B93>0,B12/'Data Sheet'!B93,0) -> 19.182957 | C13: =IF('Data Sheet'!C93>0,C12/'Data Sheet'!C93,0) -> 20.681052 | D13: =IF('Data Sheet'!D93>0,D12/'Data Sheet'!D93,0) -> 24.088704 | E13: =IF('Data Sheet'!E93>0,E12/'Data Sheet'!E93,0) -> 27.966924 | F13: =IF('Data Sheet'!F93>0,F12/'Data Sheet'!F93,0) -> 31.171471 | G13: =IF('Data Sheet'!G93>0,G12/'Data Sheet'!G93,0) -> 34.027068 | H13: =IF('Data Sheet'!H93>0,H12/'Data Sheet'!H93,0) -> 37.789411 | I13: =IF('Data Sheet'!I93>0,I12/'Data Sheet'!I93,0) -> 43.071161 | ... K13: =IF('Data Sheet'!K93>0,K12/'Data Sheet'!K93,0) -> 45.322608 | L13: =IF('Data Sheet'!$B6>0,'Profit & Loss'!L12/'Data Sheet'!$B6,0) -> 61.742642 | M13: =IF('Data Sheet'!$B6>0,'Profit & Loss'!M12/'Data Sheet'!$B6,0) -> 49.018179 | N13: =IF('Data Sheet'!$B6>0,'Profit & Loss'!N12/'Data Sheet'!$B6,0) -> 45.563174
A14: Price to earning | B14: =IF(B15>0,B15/B13,"") -> 43.380695 | C14: =IF(C15>0,C15/C13,"") -> 42.193696 | D14: =IF(D15>0,D15/D13,"") -> 52.975453 | E14: =IF(E15>0,E15/E13,"") -> 58.409356 | F14: =IF(F15>0,F15/F13,"") -> 70.571903 | G14: =IF(G15>0,G15/G13,"") -> 68.390258 | H14: =IF(H15>0,H15/H13,"") -> 51.884905 | I14: =IF(I15>0,I15/I13,"") -> 56.892824 | ... K14: =IF(K15>0,K15/K13,"") -> 47.699815 | L14: =IF(L13>0,L15/L13,0) -> 36.624607 | M14: =M25 -> 47.690981 | N14: =N25 -> 36.624607
A15: Price | B15: ='Data Sheet'!B90 -> 832.17 | C15: ='Data Sheet'!C90 -> 872.61 | D15: ='Data Sheet'!D90 -> 1276.11 | E15: ='Data Sheet'!E90 -> 1633.53 | F15: ='Data Sheet'!F90 -> 2199.83 | G15: ='Data Sheet'!G90 -> 2327.12 | H15: ='Data Sheet'!H90 -> 1960.7 | I15: ='Data Sheet'!I90 -> 2450.44 | ... K15: ='Data Sheet'!K90 -> 2161.88 | L15: ='Data Sheet'!B8 -> 2261.3 | M15: =M13*M14 -> 2337.725 | N15: =N13*N14 -> 1668.7334
A17: RATIOS:
A18: Dividend Payout | B18: =IF('Data Sheet'!B30>0, 'Data Sheet'!B31/'Data Sheet'!B30, 0) -> 0.83257046 | C18: =IF('Data Sheet'!C30>0, 'Data Sheet'!C31/'Data Sheet'!C30, 0) -> 0.82037534 | D18: =IF('Data Sheet'!D30>0, 'Data Sheet'!D31/'Data Sheet'!D30, 0) -> 0.82853855 | E18: =IF('Data Sheet'!E30>0, 'Data Sheet'!E31/'Data Sheet'!E30, 0) -> 0.78493558 | F18: =IF('Data Sheet'!F30>0, 'Data Sheet'!F31/'Data Sheet'!F30, 0) -> 0.80023711 | G18: =IF('Data Sheet'!G30>0, 'Data Sheet'!G31/'Data Sheet'!G30, 0) -> 1.1904315 | H18: =IF('Data Sheet'!H30>0, 'Data Sheet'!H31/'Data Sheet'!H30, 0) -> 0.89987611 | I18: =IF('Data Sheet'!I30>0, 'Data Sheet'!I31/'Data Sheet'!I30, 0) -> 0.90563241 | ... K18: =IF('Data Sheet'!K30>0, 'Data Sheet'!K31/'Data Sheet'!K30, 0) -> 1.1695934
A19: OPM | B19: =IF(B6>0,B6/B4,0) -> 0.18362021 | C19: =IF(C6>0,C6/C4,0) -> 0.19082082 | D19: =IF(D6>0,D6/D4,0) -> 0.21097201 | E19: =IF(E6>0,E6/E4,0) -> 0.22589672 | F19: =IF(F6>0,F6/F4,0) -> 0.24786969 | G19: =IF(G6>0,G6/G4,0) -> 0.24721443 | H19: =IF(H6>0,H6/H4,0) -> 0.24514739 | I19: =IF(I6>0,I6/I4,0) -> 0.23352592 | ... L19: =IF(L6>0,L6/L4,0) -> 0.23081929
G22: TRENDS: | H22: 10 YEARS | I22: 7 YEARS | J22: 5 YEARS | K22: 3 YEARS | L22: RECENT | M22: BEST | N22: WORST
G23: Sales Growth | H23: =IF(B4=0,"",POWER($K4/B4,1/9)-1) -> 0.077707146 | I23: =IF(D4=0,"",POWER($K4/D4,1/7)-1) -> 0.0854952 | J23: =IF(F4=0,"",POWER($K4/F4,1/5)-1) -> 0.096718749 | K23: =IF(H4=0,"",POWER($K4/H4, 1/3)-1) -> 0.063703284 | L23: =IF(ISERROR(MAX(IF(J4=0,"",(K4-J4)/J4),IF(K4=0,"",(L4-K4)/K4))),"",MAX(IF(J4=0,"",(K4-J4)/J4),IF(K4=0,"",(L4-K4)/K4))) -> 0.022544003 | M23: =MAX(K23:L23) -> 0.063703284 | N23: =MIN(H23:L23) -> 0.022544003
G24: OPM | H24: =IF(SUM(B4:$K$4)=0,"",SUMPRODUCT(B19:$K$19,B4:$K$4)/SUM(B4:$K$4)) -> 0.22924072 | I24: =IF(SUM(E4:$K$4)=0,"",SUMPRODUCT(E19:$K$19,E4:$K$4)/SUM(E4:$K$4)) -> 0.23855461 | J24: =IF(SUM(G4:$K$4)=0,"",SUMPRODUCT(G19:$K$19,G4:$K$4)/SUM(G4:$K$4)) -> 0.23900011 | K24: =IF(SUM(I4:$K$4)=0, "", SUMPRODUCT(I19:$K$19,I4:$K$4)/SUM(I4:$K$4)) -> 0.2351816 | L24: =L19 -> 0.23081929 | M24: =MAX(K24:L24) -> 0.2351816 | N24: =MIN(H24:L24) -> 0.22924072
G25: Price to Earning | H25: =IF(ISERROR(AVERAGEIF(B14:$L14,">0")),"",AVERAGEIF(B14:$L14,">0")) -> 52.59729 | I25: =IF(ISERROR(AVERAGEIF(E14:$L14,">0")),"",AVERAGEIF(E14:$L14,">0")) -> 55.002543 | J25: =IF(ISERROR(AVERAGEIF(G14:$L14,">0")),"",AVERAGEIF(G14:$L14,">0")) -> 51.839848 | K25: =IF(ISERROR(AVERAGEIF(I14:$L14,">0")),"",AVERAGEIF(I14:$L14,">0")) -> 47.690981 | L25: =L14 -> 36.624607 | M25: =MAX(K25:L25) -> 47.690981 | N25: =MIN(H25:L25) -> 36.624607
A27: Sales Growth (y-oy) | C27: =C4/B4-1 -> 0.030323743 | D27: =D4/C4-1 -> 0.071859357 | E27: =E4/D4-1 -> 0.10592207 | F27: =F4/E4-1 -> 0.012032562 | G27: =G4/F4-1 -> 0.18211296 | H27: =H4/G4-1 -> 0.11520796 | I27: =I4/H4-1 -> 0.15509286 | J27: =J4/I4-1 -> 0.021723341 | K27: =K4/J4-1 -> 0.019791263
A29: Gross Profit | B29: ='Data Sheet'!B17-'Data Sheet'!B18-'Data Sheet'!B19-'Data Sheet'!B20-'Data Sheet'!B21 -> 15810 | C29: ='Data Sheet'!C17-'Data Sheet'!C18-'Data Sheet'!C19-'Data Sheet'!C20-'Data Sheet'!C21 -> 16518 | D29: ='Data Sheet'!D17-'Data Sheet'!D18-'Data Sheet'!D19-'Data Sheet'!D20-'Data Sheet'!D21 -> 17947 | E29: ='Data Sheet'!E17-'Data Sheet'!E18-'Data Sheet'!E19-'Data Sheet'!E20-'Data Sheet'!E21 -> 20128 | F29: ='Data Sheet'!F17-'Data Sheet'!F18-'Data Sheet'!F19-'Data Sheet'!F20-'Data Sheet'!F21 -> 20773 | G29: ='Data Sheet'!G17-'Data Sheet'!G18-'Data Sheet'!G19-'Data Sheet'!G20-'Data Sheet'!G21 -> 23275 | H29: ='Data Sheet'!H17-'Data Sheet'!H18-'Data Sheet'!H19-'Data Sheet'!H20-'Data Sheet'!H21 -> 25881 | I29: ='Data Sheet'!I17-'Data Sheet'!I18-'Data Sheet'!I19-'Data Sheet'!I20-'Data Sheet'!I21 -> 27903 | ... K29: ='Data Sheet'!K17-'Data Sheet'!K18-'Data Sheet'!K19-'Data Sheet'!K20-'Data Sheet'!K21 -> 31363
A30: Gross Margin | B30: =B29/B4 -> 0.49120736 | C30: =C29/C4 -> 0.49810024 | D30: =D29/D4 -> 0.50490927 | E30: =E29/E4 -> 0.51203256 | F30: =F29/F4 -> 0.52215771 | G30: =G29/G4 -> 0.49491792 | H30: =H29/H4 -> 0.49347901 | I30: =I29/I4 -> 0.46059756 | ... K30: =K29/K4 -> 0.49687109
A31: EBIDTA | B31: =B6/B4 -> 0.18362021 | C31: =C6/C4 -> 0.19082082 | D31: =D6/D4 -> 0.21097201 | E31: =E6/E4 -> 0.22589672 | F31: =F6/F4 -> 0.24786969 | G31: =G6/G4 -> 0.24721443 | H31: =H6/H4 -> 0.24514739 | I31: =I6/I4 -> 0.23352592 | ... K31: =K6/K4 -> 0.23515153
A32: Net Margins | B32: =B12/B4 -> 0.12896912 | C32: =C12/C4 -> 0.13497377 | D32: =D12/D4 -> 0.1466873 | E32: =E12/E4 -> 0.15400661 | F32: =F12/F4 -> 0.16962019 | G32: =G12/G4 -> 0.1700051 | H32: =H12/H4 -> 0.16929794 | I32: =I12/I4 -> 0.16705183 | ... K32: =K12/K4 -> 0.16870772
A33: EBIT MARGINS | B33: =(B6-B8)/B4 -> 0.17265271 | C33: =(C6-C8)/C4 -> 0.17779386 | D33: =(D6-D8)/D4 -> 0.19634266 | E33: =(E6-E8)/E4 -> 0.21152379 | F33: =(F6-F8)/F4 -> 0.22268306 | G33: =(G6-G8)/G4 -> 0.22437697 | H33: =(H6-H8)/H4 -> 0.22434504 | I33: =(I6-I8)/I4 -> 0.21475735 | ... K33: =(K6-K8)/K4 -> 0.21368483
A34: EPS growth | C34: =C13/B13-1 -> 0.078095099 | D34: =D13/C13-1 -> 0.16477172 | E34: =E13/D13-1 -> 0.16099744 | F34: =F13/E13-1 -> 0.11458346 | G34: =G13/F13-1 -> 0.091609332 | H34: =H13/G13-1 -> 0.11056911 | I34: =I13/H13-1 -> 0.13976799 | J34: =J13/I13-1 -> 0.015513834 | K34: =K13/J13-1 -> 0.036197334
A35: Divident per share | B35: =B13*B18 -> 15.971163 | C35: =C13*C18 -> 16.966225 | D35: =D13*D18 -> 19.95842 | E35: =E13*E18 -> 21.952234 | F35: =F13*F18 -> 24.944568 | G35: =G13*G18 -> 40.506895 | H35: =H13*H18 -> 34.005788 | I35: =I13*I18 -> 39.006639 | ... K35: =K13*K18 -> 53.009023
A36: Divident Growth Rate | C36: =C35/B35-1 -> 0.062303632 | D36: =D35/C35-1 -> 0.17636188 | E36: =E35/D35-1 -> 0.099898369 | F36: =F35/E35-1 -> 0.13631114 | G36: =G35/F35-1 -> 0.6238764 | H36: =H35/G35-1 -> -0.16049383 | I36: =I35/H35-1 -> 0.14705882 | J36: =J35/I35-1 -> 0.076923077 | K36: =K35/J35-1 -> 0.26190476
A38: Market Capitalisation | B38: ='Data Sheet'!B93*'Data Sheet'!B90 -> 180073.27 | C38: ='Data Sheet'!C93*'Data Sheet'!C90 -> 188858.98 | D38: ='Data Sheet'!D93*'Data Sheet'!D90 -> 276214.01 | E38: ='Data Sheet'!E93*'Data Sheet'!E90 -> 353610.24 | F38: ='Data Sheet'!F93*'Data Sheet'!F90 -> 476219.2 | G38: ='Data Sheet'!G93*'Data Sheet'!G90 -> 546780.12 | H38: ='Data Sheet'!H93*'Data Sheet'!H90 -> 460686.07 | I38: ='Data Sheet'!I93*'Data Sheet'!I90 -> 575755.38 | ... K38: ='Data Sheet'!K93*'Data Sheet'!K90 -> 507955.32
A39: Debt | B39: ='Data Sheet'!B59 -> 177 | C39: ='Data Sheet'!C59 -> 277 | D39: ='Data Sheet'!D59 -> 0 | E39: ='Data Sheet'!E59 -> 99 | F39: ='Data Sheet'!F59 -> 0 | G39: ='Data Sheet'!G59 -> 0 | H39: ='Data Sheet'!H59 -> 1043 | I39: ='Data Sheet'!I59 -> 1219 | ... K39: ='Data Sheet'!K59 -> 1648
A40: Cash | B40: ='Data Sheet'!B69 -> 3009 | C40: ='Data Sheet'!C69 -> 1828 | D40: ='Data Sheet'!D69 -> 3485 | E40: ='Data Sheet'!E69 -> 3757 | F40: ='Data Sheet'!F69 -> 5113 | G40: ='Data Sheet'!G69 -> 4471 | H40: ='Data Sheet'!H69 -> 3846 | I40: ='Data Sheet'!I69 -> 4678 | ... K40: ='Data Sheet'!K69 -> 7554
A41: EV | B41: =B38+B39-B40 -> 177241.27 | C41: =C38+C39-C40 -> 187307.98 | D41: =D38+D39-D40 -> 272729.01 | E41: =E38+E39-E40 -> 349952.24 | F41: =F38+F39-F40 -> 471106.2 | G41: =G38+G39-G40 -> 542309.12 | H41: =H38+H39-H40 -> 457883.07 | I41: =I38+I39-I40 -> 572296.38 | ... K41: =K38+K39-K40 -> 502049.32
A43: EV/ EBIDTA | B43: =B41/B6 -> 29.990062 | C43: =C41/C6 -> 29.599871 | D43: =D41/D6 -> 36.368717 | E43: =E41/E6 -> 39.409036 | F43: =F41/F6 -> 47.774688 | G43: =G41/G6 -> 46.646234 | H43: =H41/H6 -> 35.613524 | I43: =I41/I6 -> 40.453551 | ... K43: =K41/K6 -> 33.823979
A44: EV/Sales | B44: =B41/B4 -> 5.5067814 | C44: =C41/C4 -> 5.6482716 | D44: =D41/D4 -> 7.6727812 | E44: =E41/E4 -> 8.9023719 | F44: =F41/F4 -> 11.841897 | G44: =G41/G4 -> 11.531622 | H44: =H41/H4 -> 8.7305623 | I44: =I41/I4 -> 9.4469525 | ... K44: =K41/K4 -> 7.9537606
A46: P/B | B46: =B38/'Balance Sheet'!B26 -> 27.395902 | C46: =C38/'Balance Sheet'!C26 -> 28.004001 | D46: =D38/'Balance Sheet'!D26 -> 37.936274 | E46: =E38/'Balance Sheet'!E26 -> 44.94855 | F46: =F38/'Balance Sheet'!F26 -> 57.870847 | G46: =G38/'Balance Sheet'!G26 -> 11.469147 | H46: =H38/'Balance Sheet'!H26 -> 9.3900669 | I46: =I38/'Balance Sheet'!I26 -> 11.445519 | ... K46: =K38/'Balance Sheet'!K26 -> 10.28208

Sheet Quarters
A1: ='Profit & Loss'!A1 -> HINDUSTAN UNILEVER LTD | E1: =UPDATE | J1: SCREENER.IN
A3: Narration | B3: ='Data Sheet'!B41 -> 45199 | C3: ='Data Sheet'!C41 -> 45291 | D3: ='Data Sheet'!D41 -> 45382 | E3: ='Data Sheet'!E41 -> 45473 | F3: ='Data Sheet'!F41 -> 45565 | G3: ='Data Sheet'!G41 -> 45657 | H3: ='Data Sheet'!H41 -> 45747 | I3: ='Data Sheet'!I41 -> 45838 | ... K3: ='Data Sheet'!K41 -> 46022
A4: Sales | B4: ='Data Sheet'!B42 -> 15623 | C4: ='Data Sheet'!C42 -> 15567 | D4: ='Data Sheet'!D42 -> 15210 | E4: ='Data Sheet'!E42 -> 15707 | F4: ='Data Sheet'!F42 -> 15926 | G4: ='Data Sheet'!G42 -> 15556 | H4: ='Data Sheet'!H42 -> 15670 | I4: ='Data Sheet'!I42 -> 16514 | ... K4: ='Data Sheet'!K42 -> 16441
A5: Expenses | B5: ='Data Sheet'!B43 -> 11828 | C5: ='Data Sheet'!C43 -> 11902 | D5: ='Data Sheet'!D43 -> 11675 | E5: ='Data Sheet'!E43 -> 11965 | F5: ='Data Sheet'!F43 -> 12139 | G5: ='Data Sheet'!G43 -> 11867 | H5: ='Data Sheet'!H43 -> 12052 | I5: ='Data Sheet'!I43 -> 12797 | ... K5: ='Data Sheet'!K43 -> 12660
A6: Operating Profit | B6: ='Data Sheet'!B50 -> 3795 | C6: ='Data Sheet'!C50 -> 3665 | D6: ='Data Sheet'!D50 -> 3535 | E6: ='Data Sheet'!E50 -> 3742 | F6: ='Data Sheet'!F50 -> 3787 | G6: ='Data Sheet'!G50 -> 3689 | H6: ='Data Sheet'!H50 -> 3618 | I6: ='Data Sheet'!I50 -> 3717 | ... K6: ='Data Sheet'!K50 -> 3781
A7: Other Income | B7: ='Data Sheet'!B44 -> 178 | C7: ='Data Sheet'!C44 -> 184 | D7: ='Data Sheet'!D44 -> 309 | E7: ='Data Sheet'!E44 -> 209 | F7: ='Data Sheet'!F44 -> 203 | G7: ='Data Sheet'!G44 -> 733 | H7: ='Data Sheet'!H44 -> 171 | I7: ='Data Sheet'!I44 -> 74 | ... K7: ='Data Sheet'!K44 -> 4048
A8: Depreciation | B8: ='Data Sheet'!B45 -> 297 | C8: ='Data Sheet'!C45 -> 313 | D8: ='Data Sheet'!D45 -> 320 | E8: ='Data Sheet'!E45 -> 329 | F8: ='Data Sheet'!F45 -> 338 | G8: ='Data Sheet'!G45 -> 318 | H8: ='Data Sheet'!H45 -> 347 | I8: ='Data Sheet'!I45 -> 361 | ... K8: ='Data Sheet'!K45 -> 337
A9: Interest | B9: ='Data Sheet'!B46 -> 88 | C9: ='Data Sheet'!C46 -> 91 | D9: ='Data Sheet'!D46 -> 105 | E9: ='Data Sheet'!E46 -> 93 | F9: ='Data Sheet'!F46 -> 110 | G9: ='Data Sheet'!G46 -> 109 | H9: ='Data Sheet'!H46 -> 80 | I9: ='Data Sheet'!I46 -> 127 | ... K9: ='Data Sheet'!K46 -> 88
A10: Profit before tax | B10: ='Data Sheet'!B47 -> 3588 | C10: ='Data Sheet'!C47 -> 3445 | D10: ='Data Sheet'!D47 -> 3419 | E10: ='Data Sheet'!E47 -> 3529 | F10: ='Data Sheet'!F47 -> 3542 | G10: ='Data Sheet'!G47 -> 3995 | H10: ='Data Sheet'!H47 -> 3362 | I10: ='Data Sheet'!I47 -> 3303 | ... K10: ='Data Sheet'!K47 -> 7404
A11: Tax | B11: ='Data Sheet'!B48 -> 931 | C11: ='Data Sheet'!C48 -> 937 | D11: ='Data Sheet'!D48 -> 858 | E11: ='Data Sheet'!E48 -> 917 | F11: ='Data Sheet'!F48 -> 947 | G11: ='Data Sheet'!G48 -> 1006 | H11: ='Data Sheet'!H48 -> 887 | I11: ='Data Sheet'!I48 -> 535 | ... K11: ='Data Sheet'!K48 -> 801
A12: Net profit | B12: ='Data Sheet'!B49 -> 2656 | C12: ='Data Sheet'!C49 -> 2509 | D12: ='Data Sheet'!D49 -> 2558 | E12: ='Data Sheet'!E49 -> 2610 | F12: ='Data Sheet'!F49 -> 2591 | G12: ='Data Sheet'!G49 -> 2984 | H12: ='Data Sheet'!H49 -> 2464 | I12: ='Data Sheet'!I49 -> 2756 | ... K12: ='Data Sheet'!K49 -> 6607
A14: OPM | B14: =IF(B4>0,B6/B4,"") -> 0.24291109 | C14: =IF(C4>0,C6/C4,"") -> 0.23543393 | D14: =IF(D4>0,D6/D4,"") -> 0.23241289 | E14: =IF(E4>0,E6/E4,"") -> 0.23823773 | F14: =IF(F4>0,F6/F4,"") -> 0.23778727 | G14: =IF(G4>0,G6/G4,"") -> 0.23714322 | H14: =IF(H4>0,H6/H4,"") -> 0.23088705 | I14: =IF(I4>0,I6/I4,"") -> 0.22508175 | ... K14: =IF(K4>0,K6/K4,"") -> 0.22997385

Sheet Cash Flow
A1: ='Balance Sheet'!A1 -> HINDUSTAN UNILEVER LTD | E1: =UPDATE | J1: SCREENER.IN
A3: Narration | B3: ='Data Sheet'!B81 -> 42460 | C3: ='Data Sheet'!C81 -> 42825 | D3: ='Data Sheet'!D81 -> 43190 | E3: ='Data Sheet'!E81 -> 43555 | F3: ='Data Sheet'!F81 -> 43921 | G3: ='Data Sheet'!G81 -> 44286 | H3: ='Data Sheet'!H81 -> 44651 | I3: ='Data Sheet'!I81 -> 45016 | ... K3: ='Data Sheet'!K81 -> 45747
A4: Cash from Operating Activity | B4: ='Data Sheet'!B82 -> 4171 | C4: ='Data Sheet'!C82 -> 5185 | D4: ='Data Sheet'!D82 -> 6059 | E4: ='Data Sheet'!E82 -> 5800 | F4: ='Data Sheet'!F82 -> 7623 | G4: ='Data Sheet'!G82 -> 9163 | H4: ='Data Sheet'!H82 -> 9048 | I4: ='Data Sheet'!I82 -> 9991 | ... K4: ='Data Sheet'!K82 -> 11886
A5: Cash from Investing Activity | B5: ='Data Sheet'!B83 -> -282 | C5: ='Data Sheet'!C83 -> -1173 | D5: ='Data Sheet'!D83 -> -1063 | E5: ='Data Sheet'!E83 -> -438 | F5: ='Data Sheet'!F83 -> 1791 | G5: ='Data Sheet'!G83 -> -1228 | H5: ='Data Sheet'!H83 -> -1728 | I5: ='Data Sheet'!I83 -> -1484 | ... K5: ='Data Sheet'!K83 -> 6473
A6: Cash from Financing Activity | B6: ='Data Sheet'!B84 -> -3864 | C6: ='Data Sheet'!C84 -> -4214 | D6: ='Data Sheet'!D84 -> -4975 | E6: ='Data Sheet'!E84 -> -5390 | F6: ='Data Sheet'!F84 -> -6819 | G6: ='Data Sheet'!G84 -> -9309 | H6: ='Data Sheet'!H84 -> -8015 | I6: ='Data Sheet'!I84 -> -8953 | ... K6: ='Data Sheet'!K84 -> -13101
A7: Net Cash Flow | B7: ='Data Sheet'!B85 -> 25 | C7: ='Data Sheet'!C85 -> -202 | D7: ='Data Sheet'!D85 -> 21 | E7: ='Data Sheet'!E85 -> -28 | F7: ='Data Sheet'!F85 -> 2595 | G7: ='Data Sheet'!G85 -> -1374 | H7: ='Data Sheet'!H85 -> -695 | I7: ='Data Sheet'!I85 -> -446 | ... K7: ='Data Sheet'!K85 -> 5258

Sheet Balance Sheet
A1: ='Profit & Loss'!A1 -> HINDUSTAN UNILEVER LTD | E1: =UPDATE | J1: SCREENER.IN
A3: Narration | B3: ='Data Sheet'!B56 -> 42460 | C3: ='Data Sheet'!C56 -> 42825 | D3: ='Data Sheet'!D56 -> 43190 | E3: ='Data Sheet'!E56 -> 43555 | F3: ='Data Sheet'!F56 -> 43921 | G3: ='Data Sheet'!G56 -> 44286 | H3: ='Data Sheet'!H56 -> 44651 | I3: ='Data Sheet'!I56 -> 45016 | ... K3: ='Data Sheet'!K56 -> 45747
A4: Equity Share Capital | B4: ='Data Sheet'!B57 -> 216 | C4: ='Data Sheet'!C57 -> 216 | D4: ='Data Sheet'!D57 -> 216 | E4: ='Data Sheet'!E57 -> 216 | F4: ='Data Sheet'!F57 -> 216 | G4: ='Data Sheet'!G57 -> 235 | H4: ='Data Sheet'!H57 -> 235 | I4: ='Data Sheet'!I57 -> 235 | ... K4: ='Data Sheet'!K57 -> 235
A5: Reserves | B5: ='Data Sheet'!B58 -> 6357 | C5: ='Data Sheet'!C58 -> 6528 | D5: ='Data Sheet'!D58 -> 7065 | E5: ='Data Sheet'!E58 -> 7651 | F5: ='Data Sheet'!F58 -> 8013 | G5: ='Data Sheet'!G58 -> 47439 | H5: ='Data Sheet'!H58 -> 48826 | I5: ='Data Sheet'!I58 -> 50069 | ... K5: ='Data Sheet'!K58 -> 49167
A6: Borrowings | B6: ='Data Sheet'!B59 -> 177 | C6: ='Data Sheet'!C59 -> 277 | D6: ='Data Sheet'!D59 -> 0 | E6: ='Data Sheet'!E59 -> 99 | F6: ='Data Sheet'!F59 -> 0 | G6: ='Data Sheet'!G59 -> 0 | H6: ='Data Sheet'!H59 -> 1043 | I6: ='Data Sheet'!I59 -> 1219 | ... K6: ='Data Sheet'!K59 -> 1648
A7: Other Liabilities | B7: ='Data Sheet'!B60 -> 8043 | C7: ='Data Sheet'!C60 -> 8685 | D7: ='Data Sheet'!D60 -> 10581 | E7: ='Data Sheet'!E60 -> 10663 | F7: ='Data Sheet'!F60 -> 11924 | G7: ='Data Sheet'!G60 -> 21066 | H7: ='Data Sheet'!H60 -> 20402 | I7: ='Data Sheet'!I60 -> 21554 | ... K7: ='Data Sheet'!K60 -> 28813
A8: Total | B8: ='Data Sheet'!B61 -> 14793 | C8: ='Data Sheet'!C61 -> 15706 | D8: ='Data Sheet'!D61 -> 17862 | E8: ='Data Sheet'!E61 -> 18629 | F8: ='Data Sheet'!F61 -> 20153 | G8: ='Data Sheet'!G61 -> 68740 | H8: ='Data Sheet'!H61 -> 70506 | I8: ='Data Sheet'!I61 -> 73077 | ... K8: ='Data Sheet'!K61 -> 79863
A10: Net Block | B10: ='Data Sheet'!B62 -> 3258 | C10: ='Data Sheet'!C62 -> 4419 | D10: ='Data Sheet'!D62 -> 4528 | E10: ='Data Sheet'!E62 -> 4715 | F10: ='Data Sheet'!F62 -> 5479 | G10: ='Data Sheet'!G62 -> 51443 | H10: ='Data Sheet'!H62 -> 51473 | I10: ='Data Sheet'!I62 -> 52678 | ... K10: ='Data Sheet'!K62 -> 54335
A11: Capital Work in Progress | B11: ='Data Sheet'!B63 -> 408 | C11: ='Data Sheet'!C63 -> 229 | D11: ='Data Sheet'!D63 -> 461 | E11: ='Data Sheet'!E63 -> 406 | F11: ='Data Sheet'!F63 -> 597 | G11: ='Data Sheet'!G63 -> 745 | H11: ='Data Sheet'!H63 -> 1313 | I11: ='Data Sheet'!I63 -> 1132 | ... K11: ='Data Sheet'!K63 -> 1009
A12: Investments | B12: ='Data Sheet'!B64 -> 2592 | C12: ='Data Sheet'!C64 -> 3794 | D12: ='Data Sheet'!D64 -> 2873 | E12: ='Data Sheet'!E64 -> 2716 | F12: ='Data Sheet'!F64 -> 1255 | G12: ='Data Sheet'!G64 -> 2709 | H12: ='Data Sheet'!H64 -> 3521 | I12: ='Data Sheet'!I64 -> 2882 | ... K12: ='Data Sheet'!K64 -> 3810
A13: Other Assets | B13: ='Data Sheet'!B65 -> 8535 | C13: ='Data Sheet'!C65 -> 7264 | D13: ='Data Sheet'!D65 -> 10000 | E13: ='Data Sheet'!E65 -> 10792 | F13: ='Data Sheet'!F65 -> 12822 | G13: ='Data Sheet'!G65 -> 13843 | H13: ='Data Sheet'!H65 -> 14199 | I13: ='Data Sheet'!I65 -> 16385 | ... K13: ='Data Sheet'!K65 -> 20709
A14: Total | B14: ='Data Sheet'!B66 -> 14793 | C14: ='Data Sheet'!C66 -> 15706 | D14: ='Data Sheet'!D66 -> 17862 | E14: ='Data Sheet'!E66 -> 18629 | F14: ='Data Sheet'!F66 -> 20153 | G14: ='Data Sheet'!G66 -> 68740 | H14: ='Data Sheet'!H66 -> 70506 | I14: ='Data Sheet'!I66 -> 73077 | ... K14: ='Data Sheet'!K66 -> 79863
A16: Working Capital | B16: =B13-B7 -> 492 | C16: =C13-C7 -> -1421 | D16: =D13-D7 -> -581 | E16: =E13-E7 -> 129 | F16: =F13-F7 -> 898 | G16: =G13-G7 -> -7223 | H16: =H13-H7 -> -6203 | I16: =I13-I7 -> -5169 | ... K16: =K13-K7 -> -8104
A17: Debtors | B17: ='Data Sheet'!B67 -> 1264 | C17: ='Data Sheet'!C67 -> 1085 | D17: ='Data Sheet'!D67 -> 1310 | E17: ='Data Sheet'!E67 -> 1816 | F17: ='Data Sheet'!F67 -> 1149 | G17: ='Data Sheet'!G67 -> 1758 | H17: ='Data Sheet'!H67 -> 2236 | I17: ='Data Sheet'!I67 -> 3079 | ... K17: ='Data Sheet'!K67 -> 3819
A18: Inventory | B18: ='Data Sheet'!B68 -> 2726 | C18: ='Data Sheet'!C68 -> 2541 | D18: ='Data Sheet'!D68 -> 2513 | E18: ='Data Sheet'!E68 -> 2574 | F18: ='Data Sheet'!F68 -> 2767 | G18: ='Data Sheet'!G68 -> 3579 | H18: ='Data Sheet'!H68 -> 4096 | I18: ='Data Sheet'!I68 -> 4251 | ... K18: ='Data Sheet'!K68 -> 4415
A20: Debtor Days | B20: =IF('Profit & Loss'!B4>0,'Balance Sheet'!B17/('Profit & Loss'!B4/365),0) -> 14.334183 | C20: =IF('Profit & Loss'!C4>0,'Balance Sheet'!C17/('Profit & Loss'!C4/365),0) -> 11.942133 | D20: =IF('Profit & Loss'!D4>0,'Balance Sheet'!D17/('Profit & Loss'!D4/365),0) -> 13.451962 | E20: =IF('Profit & Loss'!E4>0,'Balance Sheet'!E17/('Profit & Loss'!E4/365),0) -> 16.861867 | F20: =IF('Profit & Loss'!F4>0,'Balance Sheet'!F17/('Profit & Loss'!F4/365),0) -> 10.541814 | G20: =IF('Profit & Loss'!G4>0,'Balance Sheet'!G17/('Profit & Loss'!G4/365),0) -> 13.644425 | H20: =IF('Profit & Loss'!H4>0,'Balance Sheet'!H17/('Profit & Loss'!H4/365),0) -> 15.56153 | I20: =IF('Profit & Loss'!I4>0,'Balance Sheet'!I17/('Profit & Loss'!I4/365),0) -> 18.551255 | ... K20: =IF('Profit & Loss'!K4>0,'Balance Sheet'!K17/('Profit & Loss'!K4/365),0) -> 22.083538
A21: Inventory Turnover | B21: =IF('Balance Sheet'!B18>0,'Profit & Loss'!B4/'Balance Sheet'!B18,0) -> 11.807043 | C21: =IF('Balance Sheet'!C18>0,'Profit & Loss'!C4/'Balance Sheet'!C18,0) -> 13.050767 | D21: =IF('Balance Sheet'!D18>0,'Profit & Loss'!D4/'Balance Sheet'!D18,0) -> 14.144449 | E21: =IF('Balance Sheet'!E18>0,'Profit & Loss'!E4/'Balance Sheet'!E18,0) -> 15.27195 | F21: =IF('Balance Sheet'!F18>0,'Profit & Loss'!F4/'Balance Sheet'!F18,0) -> 14.377665 | G21: =IF('Balance Sheet'!G18>0,'Profit & Loss'!G4/'Balance Sheet'!G18,0) -> 13.139983 | H21: =IF('Balance Sheet'!H18>0,'Profit & Loss'!H4/'Balance Sheet'!H18,0) -> 12.804199 | I21: =IF('Balance Sheet'!I18>0,'Profit & Loss'!I4/'Balance Sheet'!I18,0) -> 14.250765 | ... K21: =IF('Balance Sheet'!K18>0,'Profit & Loss'!K4/'Balance Sheet'!K18,0) -> 14.296942
A23: Return on Equity | B23: =IF(SUM('Balance Sheet'!B4:B5)>0,'Profit & Loss'!B12/SUM('Balance Sheet'!B4:B5),"") -> 0.6315229 | C23: =IF(SUM('Balance Sheet'!C4:C5)>0,'Profit & Loss'!C12/SUM('Balance Sheet'!C4:C5),"") -> 0.66370107 | D23: =IF(SUM('Balance Sheet'!D4:D5)>0,'Profit & Loss'!D12/SUM('Balance Sheet'!D4:D5),"") -> 0.71611042 | E23: =IF(SUM('Balance Sheet'!E4:E5)>0,'Profit & Loss'!E12/SUM('Balance Sheet'!E4:E5),"") -> 0.76954366 | F23: =IF(SUM('Balance Sheet'!F4:F5)>0,'Profit & Loss'!F12/SUM('Balance Sheet'!F4:F5),"") -> 0.82002673 | G23: =IF(SUM('Balance Sheet'!G4:G5)>0,'Profit & Loss'!G12/SUM('Balance Sheet'!G4:G5),"") -> 0.16770147 | H23: =IF(SUM('Balance Sheet'!H4:H5)>0,'Profit & Loss'!H12/SUM('Balance Sheet'!H4:H5),"") -> 0.18097878 | I23: =IF(SUM('Balance Sheet'!I4:I5)>0,'Profit & Loss'!I12/SUM('Balance Sheet'!I4:I5),"") -> 0.20117684 | ... K23: =IF(SUM('Balance Sheet'!K4:K5)>0,'Profit & Loss'!K12/SUM('Balance Sheet'!K4:K5),"") -> 0.21555807
A24: Return on Capital Emp | C24: =IF((B4+B5+B6+C4+C5+C6)>0,('Profit & Loss'!C10+'Profit & Loss'!C9)*2/(B4+B5+B6+C4+C5+C6),"") -> 0.94430325 | D24: =IF((C4+C5+C6+D4+D5+D6)>0,('Profit & Loss'!D10+'Profit & Loss'!D9)*2/(C4+C5+C6+D4+D5+D6),"") -> 1.0253111 | E24: =IF((D4+D5+D6+E4+E5+E6)>0,('Profit & Loss'!E10+'Profit & Loss'!E9)*2/(D4+D5+D6+E4+E5+E6),"") -> 1.1329442 | F24: =IF((E4+E5+E6+F4+F5+F6)>0,('Profit & Loss'!F10+'Profit & Loss'!F9)*2/(E4+E5+E6+F4+F5+F6),"") -> 1.1464032 | G24: =IF((F4+F5+F6+G4+G5+G6)>0,('Profit & Loss'!G10+'Profit & Loss'!G9)*2/(F4+F5+F6+G4+G5+G6),"") -> 0.38359301 | H24: =IF((G4+G5+G6+H4+H5+H6)>0,('Profit & Loss'!H10+'Profit & Loss'!H9)*2/(G4+G5+G6+H4+H5+H6),"") -> 0.24514717 | I24: =IF((H4+H5+H6+I4+I5+I6)>0,('Profit & Loss'!I10+'Profit & Loss'!I9)*2/(H4+H5+H6+I4+I5+I6),"") -> 0.26485088 | J24: =IF((I4+I5+I6+J4+J5+J6)>0,('Profit & Loss'!J10+'Profit & Loss'!J9)*2/(I4+I5+I6+J4+J5+J6),"") -> 0.27363876 | K24: =IF((J4+J5+J6+K4+K5+K6)>0,('Profit & Loss'!K10+'Profit & Loss'!K9)*2/(J4+J5+J6+K4+K5+K6),"") -> 0.28548847
A26: Book Value | B26: =SUM(B4:B5) -> 6573 | C26: =SUM(C4:C5) -> 6744 | D26: =SUM(D4:D5) -> 7281 | E26: =SUM(E4:E5) -> 7867 | F26: =SUM(F4:F5) -> 8229 | G26: =SUM(G4:G5) -> 47674 | H26: =SUM(H4:H5) -> 49061 | I26: =SUM(I4:I5) -> 50304 | ... K26: =SUM(K4:K5) -> 49402

Sheet Input Sheet
B4: Company Description | C4: Hindustan Unilever Limited (HUL) is an Indian fast-moving consumer goods company, headquartered in Mumbai. It is a subsidiary of the Anglo-Dutch company Unilever. Its products include foods, beverages, cleaning agents, personal care products and other consumer staples.

Sheet Raw Data
B2: Date | C2: VOL | O2: Price
B3: 44259 | C3: 2.29 | D3: 1000000 | O3: 2196.9
B4: 44260 | C4: 2.13 | O4: 2201.1
B5: 44263 | C5: 1.44 | O5: 2174.55
B6: 44264 | C6: 1.71 | O6: 2198.5
B7: 44265 | C7: 2.7 | O7: 2227.85
B8: 44267 | C8: 2.04 | O8: 2204.75
B9: 44270 | C9: 1.63 | O9: 2210.85
B10: 44271 | C10: 2.63 | O10: 2244.05
B11: 44272 | C11: 3.7 | O11: 2226.3
B12: 44273 | C12: 2.6 | O12: 2215.2
B13: 44274 | C13: 5.38 | I13: Name | O13: 2312.05
B14: 44277 | C14: 2.47 | H14: 1 | I14: Nitin Paranjpe@ | O14: 2353.2
B15: 44278 | C15: 1.97 | H15: 2 | I15: Rohit Jawa | J15: 146.47 | K15: 3.75 | O15: 2337.3
B16: 44279 | C16: 1.76 | H16: 3 | I16: Ritesh Tiwari | J16: 59.18 | K16: 9.7 | O16: 2318.6
B17: 44280 | C17: 2.5 | H17: 4 | I17: BP Biddappa* | J17: 66.32 | K17: Not comparable** | O17: 2237.05
B18: 44281 | C18: 1.93 | H18: 5 | I18: Dev Bajpai# | J18: 83.65 | K18: Not comparable** | O18: 2317.9
B19: 44285 | C19: 3.33 | O19: 2398.75
B20: 44286 | C20: 2.71 | O20: 2431.5
B21: 44287 | C21: 1.53 | O21: 2399.1
B22: 44291 | C22: 2.55 | O22: 2373.2
B23: 44292 | C23: 3.68 | O23: 2408.3
B24: 44293 | C24: 1.71 | O24: 2405.25
B25: 44294 | C25: 1.81 | O25: 2409.9
B26: 44295 | C26: 2.6 | O26: 2476
B27: 44298 | C27: 2.26 | G27: Name of | O27: 2462
B28: 44299 | C28: 1.81 | G28: Director/KMP | O28: 2454.4
B29: 44301 | C29: 3.35 | G29: Nitin Paranjpe@ | O29: 2460.65
B30: 44302 | C30: 1.23 | G30: Rohit Jawa | O30: 2458.9
B31: 44305 | C31: 1.75 | G31: Ritesh Tiwari | O31: 2436.65
B32: 44306 | C32: 1.59 | G32: BP Biddappa* | O32: 2397.45
B33: 44308 | C33: 1.72 | G33: Dev Bajpai# | O33: 2349.4
B34: 44309 | C34: 1.95 | G34: Leo Puri | O34: 2307.75
B35: 44312 | C35: 1.95 | G35: Ashu Suyash | O35: 2360.65
B36: 44313 | C36: 1.67 | G36: Ranjay Gulati | O36: 2379.85
B37: 44314 | C37: 1.95 | G37: Neelam Dhawan | O37: 2406.55
B38: 44315 | C38: 3.15 | G38: Tarun Bajaj | O38: 2407.6
... B62: 44350 | C62: 0.86853 | G62: N.A. | O62: 2363.25
B63: 44351 | C63: 1.28 | G63: 146.47 | O63: 2342.05
B64: 44354 | C64: 1.13 | G64: 59.18 | O64: 2339.3
...
